#исключения 
>Нередко бывает так, что, перехватив особую ситуацию, обработчик решает, что с этой ошибкой он ничего не сможет поделать. В таком случае самое естественное - запустить особую ситуацию снова в надежде, что с ней сумеет разобраться другой обработчик.
>— Бьерн Страуструп

С помощью функции rethrow_exception() вызывается последний перехваченный объект исключения или копия этого объекта. 